100%|████████████████████████████████████████████████████████████████████████████████| 344/344 [00:44<00:00, 11.29it/s]/home/ckqsudo/miniconda3/envs/SAE/lib/python3.11/site-packages/peft/utils/other.py:716: UserWarning: Unable to fetch remote file due to the following error (MaxRetryError("HTTPSConnectionPool(host='huggingface.co', port=443): Max retries exceeded with url: /gpt2/resolve/main/config.json (Caused by ConnectTimeoutError(<urllib3.connection.HTTPSConnection object at 0x74532e75a0d0>, 'Connection to huggingface.co timed out. (connect timeout=10)'))"), '(Request ID: 33e169ff-8bb3-4e32-b914-79676f33bf70)') - silently ignoring the lookup for the file config.json in gpt2.
  warnings.warn(                                                                                                       
{'eval_loss': 0.5673199892044067, 'eval_runtime': 2.997, 'eval_samples_per_second': 456.451, 'eval_steps_per_second': 57.056, 'epoch': 1.0}
/home/ckqsudo/miniconda3/envs/SAE/lib/python3.11/site-packages/peft/utils/save_and_load.py:246: UserWarning: Could not find a config file in gpt2 - will assume that the vocabulary was not modified.
  warnings.warn(
100%|████████████████████████████████████████████████████████████████████████████████| 344/344 [00:57<00:00,  6.00it/s]
/home/ckqsudo/miniconda3/envs/SAE/lib/python3.11/site-packages/peft/utils/other.py:716: UserWarning: Unable to fetch remote file due to the following error (MaxRetryError("HTTPSConnectionPool(host='huggingface.co', port=443): Max retries exceeded with url: /gpt2/resolve/main/config.json (Caused by NewConnectionError('<urllib3.connection.HTTPSConnection object at 0x74532e75ad50>: Failed to establish a new connection: [Errno 101] Network is unreachable'))"), '(Request ID: af6472e5-dc3b-4c8c-b1b5-dc0deea15910)') - silently ignoring the lookup for the file config.json in gpt2.
{'eval_loss': 0.5604300498962402, 'eval_runtime': 3.0904, 'eval_samples_per_second': 442.659, 'eval_steps_per_second': 55.332, 'epoch': 2.0}
{'train_runtime': 59.2071, 'train_samples_per_second': 92.624, 'train_steps_per_second': 5.81, 'train_loss': 0.6953313960585483, 'epoch': 2.0}
  warnings.warn(
/home/ckqsudo/miniconda3/envs/SAE/lib/python3.11/site-packages/peft/utils/save_and_load.py:246: UserWarning: Could not find a config file in gpt2 - will assume that the vocabulary was not modified.
  warnings.warn(
/home/ckqsudo/code2024/CKQ_ACL2024/Control_Infer/SAE-simple/src/politeness_test/polite_tune_ckpt/lora_gpt2_small_checkpoint_2impolite
