100%|███████████████████████████████████████████████████████████████████████████████████████████████████████▋| 339/340 [00:33<00:00, 11.25it/s]/home/ckqsudo/miniconda3/envs/SAE/lib/python3.11/site-packages/peft/utils/other.py:716: UserWarning: Unable to fetch remote file due to the following error (MaxRetryError("HTTPSConnectionPool(host='huggingface.co', port=443): Max retries exceeded with url: /gpt2/resolve/main/config.json (Caused by NewConnectionError('<urllib3.connection.HTTPSConnection object at 0x7d1e247b5e90>: Failed to establish a new connection: [Errno 101] Network is unreachable'))"), '(Request ID: e610138b-4a58-4838-a98f-e818d6a02413)') - silently ignoring the lookup for the file config.json in gpt2.
  warnings.warn(                                                                                                                               
{'eval_loss': 0.5855215787887573, 'eval_runtime': 2.9855, 'eval_samples_per_second': 459.882, 'eval_steps_per_second': 57.611, 'epoch': 1.0}
/home/ckqsudo/miniconda3/envs/SAE/lib/python3.11/site-packages/peft/utils/save_and_load.py:246: UserWarning: Could not find a config file in gpt2 - will assume that the vocabulary was not modified.
  warnings.warn(
100%|████████████████████████████████████████████████████████████████████████████████████████████████████████| 340/340 [00:47<00:00,  7.21it/s]
/home/ckqsudo/miniconda3/envs/SAE/lib/python3.11/site-packages/peft/utils/other.py:716: UserWarning: Unable to fetch remote file due to the following error (MaxRetryError("HTTPSConnectionPool(host='huggingface.co', port=443): Max retries exceeded with url: /gpt2/resolve/main/config.json (Caused by NewConnectionError('<urllib3.connection.HTTPSConnection object at 0x7d1e24778610>: Failed to establish a new connection: [Errno 101] Network is unreachable'))"), '(Request ID: 86d77708-bef5-41f9-a98e-ee92b377354c)') - silently ignoring the lookup for the file config.json in gpt2.
{'eval_loss': 0.5778689384460449, 'eval_runtime': 3.1094, 'eval_samples_per_second': 441.571, 'eval_steps_per_second': 55.317, 'epoch': 2.0}
{'train_runtime': 48.6828, 'train_samples_per_second': 111.169, 'train_steps_per_second': 6.984, 'train_loss': 0.7046350366928998, 'epoch': 2.0}
  warnings.warn(
/home/ckqsudo/miniconda3/envs/SAE/lib/python3.11/site-packages/peft/utils/save_and_load.py:246: UserWarning: Could not find a config file in gpt2 - will assume that the vocabulary was not modified.
  warnings.warn(
/home/ckqsudo/code2024/CKQ_ACL2024/Control_Infer/SAE-simple/src/politeness_test/polite_tune_ckpt/lora_gpt2_small_checkpoint_2polite_0209
训练时间开销 49.846386432647705
