 98%|███████████████████████████████████████████████████████████████████████████████████████████████████████▎ | 61/62 [00:06<00:00, 11.31it/s]/home/ckqsudo/miniconda3/envs/SAE/lib/python3.11/site-packages/peft/utils/other.py:716: UserWarning: Unable to fetch remote file due to the following error (MaxRetryError("HTTPSConnectionPool(host='huggingface.co', port=443): Max retries exceeded with url: /gpt2/resolve/main/config.json (Caused by NewConnectionError('<urllib3.connection.HTTPSConnection object at 0x773f6c382dd0>: Failed to establish a new connection: [Errno 101] Network is unreachable'))"), '(Request ID: f5142db6-293b-4f30-86c3-0fe2f402d148)') - silently ignoring the lookup for the file config.json in gpt2.
  warnings.warn(                                                                                                                              
{'eval_loss': 0.48008614778518677, 'eval_runtime': 0.1211, 'eval_samples_per_second': 445.778, 'eval_steps_per_second': 57.786, 'epoch': 1.0}
/home/ckqsudo/miniconda3/envs/SAE/lib/python3.11/site-packages/peft/utils/save_and_load.py:246: UserWarning: Could not find a config file in gpt2 - will assume that the vocabulary was not modified.
  warnings.warn(
100%|█████████████████████████████████████████████████████████████████████████████████████████████████████████| 62/62 [00:16<00:00,  3.77it/s]
/home/ckqsudo/miniconda3/envs/SAE/lib/python3.11/site-packages/peft/utils/other.py:716: UserWarning: Unable to fetch remote file due to the following error (MaxRetryError("HTTPSConnectionPool(host='huggingface.co', port=443): Max retries exceeded with url: /gpt2/resolve/main/config.json (Caused by NewConnectionError('<urllib3.connection.HTTPSConnection object at 0x773f6c35e250>: Failed to establish a new connection: [Errno 101] Network is unreachable'))"), '(Request ID: 66f85348-0a1f-4798-9f4c-97a85b952bca)') - silently ignoring the lookup for the file config.json in gpt2.
{'eval_loss': 0.4682298004627228, 'eval_runtime': 0.126, 'eval_samples_per_second': 428.522, 'eval_steps_per_second': 55.549, 'epoch': 2.0}
{'train_runtime': 23.1623, 'train_samples_per_second': 41.965, 'train_steps_per_second': 2.677, 'train_loss': 1.0689297337685861, 'epoch': 2.0}
  warnings.warn(
/home/ckqsudo/miniconda3/envs/SAE/lib/python3.11/site-packages/peft/utils/save_and_load.py:246: UserWarning: Could not find a config file in gpt2 - will assume that the vocabulary was not modified.
  warnings.warn(
/home/ckqsudo/code2024/CKQ_ACL2024/Control_Infer/SAE-simple/src/debate_test/debate_2support_gpt2_ckpt/lora_gpt2_small_checkpoint_2support
